<?xml version="1.0"?>
<robot xmlns:xacro="http://www.ros.org/wiki/xacro">
    
    <xacro:include filename="inertial_macros.xacro"/>

    <material name="white">
        <color rgba="1 1 1 1"/>
    </material>

    <material name="orange">
        <color rgba="1 0.3 0.1 1"/>
    </material>

    <material name="blue">
        <color rgba="0.2 0.2 1 1"/>
    </material>

    <material name="black">
        <color rgba="0 0 0 1"/>
    </material>

    <!-- Base Link -->
    <link name="base_link">

    </link>

    <!-- Base_Footprint Link-->

    <joint name="base_footprint_joint" type="fixed">
	<parent link="base_link"/>
	<child link="base_footprint"/>
	<origin xyz="0 0 0" rpy="0 0 0"/>
    </joint>

    <link name="base_footprint">
    </link>

    <!-- Chassis Link -->

    <joint name="chassis_joint" type="fixed">
        <parent link="base_link"/>
        <child link="chassis"/>
        <origin xyz="-0.29 0 0"/>
    </joint>


    <link name="chassis">
        <visual>
            <origin xyz="0.22 0 0.074"/>
            <geometry>
                <box size="0.44 0.3 0.144"/>
            </geometry>
            <material name="white"/>
        </visual>

        <collision>
            <origin xyz="0.22 0 0.074"/>
            <geometry>
                <box size="0.44 0.3 0.144"/>
            </geometry> 
        </collision>
        <xacro:inertial_box mass="2" x="0.44" y="0.3" z="0.144">
            <origin xyz="0.22 0 0.074" rpy="0 0 0"/>
        </xacro:inertial_box>
    </link>

    <!-- Left Wheel Link -->

    <joint name="left_wheel_joint" type="continuous">
        <parent link="base_link"/>
        <child link="Left_wheel"/>
        <origin xyz="0 0.192 0.056" rpy="-${pi/2} 0 0"/>
        <axis xyz="0 0 1"/>
    </joint>

    <link name="Left_wheel">
        <visual>
            <geometry>
                <cylinder radius="0.084" length="0.077"/>
            </geometry>
            <material name="blue"/>
        </visual>

        <collision>
            <geometry>
                <cylinder radius="0.084" length="0.077"/>
            </geometry>
        </collision>
        <xacro:inertial_cylinder mass="0.5" length="0.077" radius="0.084">
            <origin xyz="0 0 0" rpy="0 0 0"/>
        </xacro:inertial_cylinder>
    </link>


    <!-- Right Wheel Link -->

    <joint name="right_wheel_joint" type="continuous">
        <parent link="base_link"/>
        <child link="Right_wheel"/>
        <origin xyz="0 -0.192 0.056" rpy="${pi/2} 0 0"/>
        <axis xyz="0 0 -1"/>
    </joint>

    <link name="Right_wheel">
        <visual>
            <geometry>
                <cylinder radius="0.084" length="0.077"/>
            </geometry>
            <material name="blue"/>
        </visual>
        <collision>
            <geometry>
                <cylinder radius="0.084" length="0.077"/>
            </geometry>
        </collision>
        <xacro:inertial_cylinder mass="0.5" length="0.077" radius="0.084">
            <origin xyz="0 0 0" rpy="0 0 0"/>
        </xacro:inertial_cylinder>
    </link>

     <!-- CASTER WHEEL LINK -->

    <joint name="caster_wheel_joint" type="fixed">
        <parent link="chassis"/>
        <child link="caster_wheel"/>
        <origin xyz="0 0 0"/>
    </joint>


    <link name="caster_wheel">
        <visual>
            <geometry>
                <sphere radius="0.028"/>
            </geometry>
            <material name="black"/>
        </visual>
        <collision>
            <geometry>
                <sphere radius="0.028"/>
            </geometry>
        </collision>
        <xacro:inertial_sphere mass="0.1" radius="0.028">
            <origin xyz="0 0 0" rpy="0 0 0"/>
        </xacro:inertial_sphere>
    </link>   

</robot>
